#VRML_SIM R2019a utf8
# license: Apache License 2.0
# license url: http://www.apache.org/licenses/LICENSE-2.0
# This is a proto file for Webots for the Asterix
# Extracted from: asterix.urdf

PROTO Asterix [
  field  SFVec3f     translation  0 0 0
  field  SFRotation  rotation     0 1 0 0
  field  SFString    controller   "void"
]
{
  Robot {
    translation IS translation
    rotation IS rotation
    controller IS controller
    children [
      Shape {
        appearance DEF blue PBRAppearance {
          baseColor 0.500000 0.500000 0.500000
          transparency 0.000000
          roughness 1.000000
          metalness 0
          emissiveColor 0.000000 0.000000 0.000000
        }
        geometry Box {
           size 0.2 0.26 0.32
        }
      }
      HingeJoint {
        jointParameters HingeJointParameters {
          axis 0.000000 1.000000 0.000000
          anchor 0.000000 0.130000 -0.130000
          dampingConstant 0.7
          staticFriction 0.0
        }
        device [
          RotationalMotor {
            name "wheel_left_joint"
          }
          PositionSensor {
            name "wheel_left_joint_sensor"
          }
        ]
        endPoint Solid {
          translation 0.000000 0.130000 -0.130000
          rotation 0.000000 1.000000 0.000000 0.000000
          children [
            Transform {
              translation 0.000000 0.000000 0.000000
              rotation 1.000000 0.000000 0.000000 3.140796
              children [
                Shape {
                  appearance DEF dark PBRAppearance {
                    baseColor 0.500000 0.500000 0.500000
                    transparency 0.000000
                    roughness 1.000000
                    metalness 0
                    emissiveColor 0.000000 0.000000 0.000000
                  }
                  geometry Cylinder {
                    radius 0.04
                    height 0.01
                  }
                }
              ]
            }
          ]
          name "wheel_left_link"
          physics Physics {
            density -1
            mass 0.200000
            centerOfMass [ 0.000000 0.000000 0.000000 ]
          }
        }
      }
      HingeJoint {
        jointParameters HingeJointParameters {
          axis 0.000000 1.000000 0.000000
          anchor 0.000000 -0.130000 -0.130000
          dampingConstant 0.7
          staticFriction 0.0
        }
        device [
          RotationalMotor {
            name "right_wheel_motor"
          }
          PositionSensor {
            name "right_wheel_motor_sensor"
          }
        ]
        endPoint Solid {
          translation 0.000000 -0.130000 -0.130000
          rotation 0.000000 1.000000 0.000000 0.000000
          children [
            Transform {
              translation 0.000000 0.000000 0.000000
              rotation 1.000000 0.000000 0.000000 3.140796
              children [
                Shape {
                  appearance USE dark
                  geometry Cylinder {
                    radius 0.04
                    height 0.01
                  }
                }
              ]
            }
          ]
          name "wheel_right_link"
          physics Physics {
            density -1
            mass 0.200000
            centerOfMass [ 0.000000 0.000000 0.000000 ]
          }
        }
      }
      Solid {
        translation 0.096000 0.100000 0.050000
        rotation 0.000000 1.000000 0.000000 0.000000
        children [
          Shape {
            appearance DEF white PBRAppearance {
              baseColor 0.500000 0.500000 0.500000
              transparency 0.000000
              roughness 1.000000
              metalness 0
              emissiveColor 0.000000 0.000000 0.000000
            }
            geometry Box {
               size 0.01 0.05 0.02
            }
          }
        ]
        name "sensor_front_left"
        physics Physics {
          density -1
          mass 1.000000
          centerOfMass [ 0.000000 0.000000 0.000000 ]
        }
      }
      Solid {
        translation 0.096000 -0.100000 0.050000
        rotation 0.000000 1.000000 0.000000 0.000000
        children [
          Shape {
            appearance USE white
            geometry Box {
               size 0.01 0.05 0.02
            }
          }
        ]
        name "sensor_front_right"
        physics Physics {
          density -1
          mass 1.000000
          centerOfMass [ 0.000000 0.000000 0.000000 ]
        }
      }
      Solid {
        translation -0.096000 0.100000 0.050000
        rotation 0.000000 1.000000 0.000000 0.000000
        children [
          Shape {
            appearance USE white
            geometry Box {
               size 0.01 0.05 0.02
            }
          }
        ]
        name "sensor_back_left"
        physics Physics {
          density -1
          mass 1.000000
          centerOfMass [ 0.000000 0.000000 0.000000 ]
        }
      }
      Solid {
        translation -0.096000 -0.100000 0.050000
        rotation 0.000000 1.000000 0.000000 0.000000
        children [
          Shape {
            appearance USE white
            geometry Box {
               size 0.01 0.05 0.02
            }
          }
        ]
        name "sensor_back_right"
        physics Physics {
          density -1
          mass 1.000000
          centerOfMass [ 0.000000 0.000000 0.000000 ]
        }
      }
    ]
    name "robotbase"
    boundingObject Box {
       size 0.250000 0.310000 0.300000
    }
    physics Physics {
      density -1
      mass 4.000000
      centerOfMass [ 0.000000 0.000000 0.000000 ]
    }
  }
}
