<?xml version="1.0" ?>

<robot name="Asterix" xmlns:xacro="http://www.ros.org/wiki/xacro">

  <material name="black">
      <color rgba="0.0 0.0 0.0 1.0"/>
  </material>

  <material name="dark">
    <color rgba="0.3 0.3 0.3 1.0"/>
  </material>

  <material name="light_black">
    <color rgba="0.4 0.4 0.4 1.0"/>
  </material>

  <material name="blue">
    <color rgba="0.0 0.0 0.8 1.0"/>
  </material>

  <material name="green">
    <color rgba="0.0 0.8 0.0 1.0"/>
  </material>

  <material name="grey">
    <color rgba="0.5 0.5 0.5 1.0"/>
  </material>

  <material name="orange">
    <color rgba="1.0 0.4235 0.0392 1.0"/>
  </material>

  <material name="brown">
    <color rgba="0.8706 0.8118 0.7647 1.0"/>
  </material>

  <material name="red">
    <color rgba="0.8 0.0 0.0 1.0"/>
  </material>

  <material name="white">
    <color rgba="1.0 1.0 1.0 1.0"/>
  </material>

  <link name="base_footprint"/>

  <joint name="base_joint" type="fixed">
    <parent link="base_footprint"/>
    <child link="robotbase"/>
    <origin xyz="0.0 0.0 0.16" rpy="0 0 0"/>
  </joint>

  <link name="robotbase">
    <visual>
      <origin xyz="0.0 0.0 0.0" rpy="0.0 0.0 0.0"/>
      <geometry>
        <box size="0.2 0.26 0.32"/>
      </geometry>
      <material name="blue"/>
    </visual>

    <collision>
      <origin xyz="0.0 0.0 0.0" rpy="0.0 0.0 0.0"/>
        <geometry>
          <box size="0.25 0.30 0.35"/>
        </geometry>
    </collision>

  </link>


  <joint name="wheel_left_joint" type="continuous">
    <parent link="robotbase"/>
    <child link="wheel_left_link"/>
    <origin xyz="0.0 0.13 -0.13" rpy="0 0 0"/>
    <axis xyz="0 1 0"/>
    <dynamics damping="0.7"/>
  </joint>

  <link name="wheel_left_link">
    <visual>
      <origin xyz="0 0 0" rpy="1.57 0 0"/>
      <geometry>
        <cylinder length="0.01" radius="0.04"/>
      </geometry>
      <material name="dark"/>
    </visual>
  </link>

  <joint name="wheel_right_joint" type="continuous">
    <parent link="robotbase"/>
    <child link="wheel_right_link"/>
    <origin xyz="0.0 -0.13 -0.13" rpy="0 0 0"/>
    <axis xyz="0 1 0"/>
    <dynamics damping="0.7"/>
  </joint>

  <link name="wheel_right_link">
    <visual>
      <origin xyz="0 0 0" rpy="1.57 0 0"/>
      <geometry>
        <cylinder length="0.01" radius="0.04"/>
      </geometry>
      <material name="dark"/>
    </visual>
  </link>
</robot>
